<?xml version="1.0" ?>
<robot name="door_room6">

  <gazebo reference="base_r6">
    <material>Gazebo/GrassFloor</material>
  </gazebo>
  <link name="world"/>
  <joint name="link_joint_r6" type="prismatic">
    <axis xyz="1 0 0"/>
    <parent link="world"/>
    <origin rpy="0 0 1.57" xyz="3.77 10.3 0.96"/>
    <limit effort="1000.0" lower="-0" upper="1" velocity="0.5"/>
    <child link="link_r6"/>
    <dynamics damping="10" friction="1000"/>
  </joint>
  <link name="link_r6">
    <inertial>
      <mass value="10"/>
      <origin xyz="0 0 0"/>
      <inertia ixx="1.0" ixy="0.0" ixz="0.0" iyy="0.1" iyz="0.0" izz="0.1"/>
    </inertial>
    <visual>
      <origin rpy="0 0 0" xyz="0 0 0"/>
      <geometry>
        <box size="1 0.06 1.8"/>
      </geometry>
    </visual>
    <collision>
      <origin rpy="0 0 0" xyz="0 0 0"/>
      <geometry>
        <box size="1 0.06 1.8"/>
      </geometry>
    </collision>
  </link>
  <gazebo reference="link_r6">
    <material>Gazebo/RustySteel</material>
    <turnGravityOff>true</turnGravityOff>
  </gazebo>
</robot>

