<?xml version="1.0" ?>
<robot name="door_room2">

  <gazebo reference="base_r2">
    <material>Gazebo/GrassFloor</material>
  </gazebo>
  <link name="world"/>
  <joint name="link_joint_r2" type="revolute">
    <axis xyz="0 0 1"/>
    <parent link="world"/>
    <origin rpy="0 0 0" xyz="0.5 0.03 0.06"/>
    <limit effort="1000.0" lower="-1.57" upper="1.57" velocity="0.5"/>
    <child link="link_r2"/>
    <dynamics damping="10" friction="1000"/>
  </joint>
  <link name="link_r2">
    <inertial>
      <mass value="10"/>
      <origin xyz="6.15 8.53 0.96"/>
      <inertia ixx="1.0" ixy="0.0" ixz="0.0" iyy="0.1" iyz="0.0" izz="0.1"/>
    </inertial>
    <visual>
      <origin rpy="0 0 0" xyz="6.15 8.53 0.96"/>
      <geometry>
        <box size="1 0.06 1.8"/>
      </geometry>
    </visual>
    <collision>
      <origin rpy="0 0 0" xyz="6.15 8.53 0.96"/>
      <geometry>
        <box size="1 0.06 1.8"/>
      </geometry>
    </collision>
  </link>
  <gazebo reference="link_r2">
    <material>Gazebo/RustySteel</material>
    <turnGravityOff>true</turnGravityOff>
  </gazebo>
</robot>

