<?xml version="1.0" ?>
<robot name="elevator">  
<link name="world"/>
<joint name="elevator_joint" type="prismatic">
    <axis xyz="0 0 1"/>
    <parent link="world"/>
    <origin rpy="0 0 0" xyz="0 0 0"/>
    <limit effort="100.0" lower="0" upper="2.25" velocity="5"/>
    <child link="elevator_5"/>
    <dynamics damping="10" friction="1000"/>
  </joint>
  <link name="elevator_1">
     <inertial>
      <origin xyz="0 0 0" rpy="0 0 0" /> 
      <mass value="10.0" />
      <inertia  ixx="1.0" ixy="0.0"  ixz="0.0"  iyy="1.0"  iyz="0.0"  izz="1.0" />
    </inertial>
    <visual>
     <origin xyz="0 0 1.125" rpy="0 0 1.57" /> 
      <geometry>
        <box size="2 0.06 2.25" />
      </geometry>
    </visual>
    <collision>
      <origin xyz="0 0 1.125" rpy="0 0 1.57" /> 
      <geometry>
        <box size="2 0.06 2.25" />
      </geometry>
    </collision>
  </link>
  <joint name="e5_e1" type="fixed">
    <axis xyz="0 0 1"/>
    <origin rpy="0 0 0" xyz="-.97 .97 1.125"/>
    <parent link="elevator_5"/>
    <child link="elevator_1"/>
  </joint>  
  <link name="elevator_2">
     <inertial>
      <origin xyz="0 0 0" rpy="0 0 0" /> 
      <mass value="0.0" />
      <inertia  ixx="1.0" ixy="0.0"  ixz="0.0"  iyy="1.0"  iyz="0.0"  izz="1.0" />
    </inertial>
    <visual>
     <origin xyz="0 0 0" rpy="0 0 0" /> 
      <geometry>
        <box size="1.88 0.06 2.25" />
      </geometry>
    </visual>
    <collision>
      <origin xyz="0 0 0" rpy="0 0 0" /> 
      <geometry>
        <box size="1.88 0.06 2.25" />
      </geometry>
    </collision>
  </link>
  <joint name="e5_e2" type="fixed">
    <axis xyz="0 0 1"/>
    <parent link="elevator_5"/>
    <child link="elevator_2"/>
  </joint> 
  <link name="elevator_3">
     <inertial>
      <origin xyz="0 0 0" rpy="0 0 0" /> 
      <mass value="10.0" />
      <inertia  ixx="1.0" ixy="0.0"  ixz="0.0"  iyy="1.0"  iyz="0.0"  izz="1.0" />
    </inertial>
    <visual>
     <origin xyz="-.97 -.97 1.125" rpy="0 0 0" /> 
      <geometry>
        <box size="1.88 0.06 2.25" />
      </geometry>
    </visual>
    <collision>
      <origin xyz="-.97 -.97 1.125" rpy="0 0 0" /> 
      <geometry>
        <box size="1.88 0.06 2.25" />
      </geometry>
    </collision>
  </link>
  <joint name="e5_e3" type="fixed">
    <axis xyz="0 0 1"/>
    <parent link="elevator_5"/>
    <child link="elevator_3"/>
  </joint>  
  <link name="elevator_4">
     <inertial>
      <origin xyz="0 0 0" rpy="0 0 0" /> 
      <mass value="10.0" />
      <inertia  ixx="1.0" ixy="0.0"  ixz="0.0"  iyy="1.0"  iyz="0.0"  izz="1.0" />
    </inertial>
    <visual>
     <origin xyz="-.97 0 2.28" rpy="0 0 0" /> 
      <geometry>
        <box size="2 2 .06" />
      </geometry>
    </visual>
    <collision>
      <origin xyz="-.97 0 2.28" rpy="0 0 0" /> 
      <geometry>
        <box size="2 2 .06" />
      </geometry>
    </collision>
  </link>
  <joint name="e5_e4" type="fixed">
    <axis xyz="0 0 1"/>
    <parent link="elevator_5"/>
    <child link="elevator_4"/>
  </joint>  
  <link name="elevator_5">
     <inertial>
      <origin xyz="0 0 0" rpy="0 0 0" /> 
      <mass value="10.0" />
      <inertia  ixx="1.0" ixy="0.0"  ixz="0.0"  iyy="100.0"  iyz="0.0"  izz="1.0" />
    </inertial>
    <visual>
     <origin xyz="-1 0 .025" rpy="0 0 0" /> 
      <geometry>
        <box size="1.94 1.88 0.05" />
      </geometry>
    </visual>
    <collision>
      <origin xyz="-1 0 .025" rpy="0 0 0" /> 
      <geometry>
        <box size="1.94 1.88 0.05" />
      </geometry>
    </collision>
  </link>-->
  <gazebo reference="elevator_1">
    <material>Gazebo/CeilingTiled</material>
  </gazebo>  
      <gazebo reference="elevator_2">
    <material>Gazebo/CeilingTiled</material>
    </gazebo> 
    <gazebo reference="elevator_3">
    <material>Gazebo/CeilingTiled</material>
    </gazebo> 
    <gazebo reference="elevator_4">
    <material>Gazebo/CeilingTiled</material>
    </gazebo>
    <gazebo reference="elevator_5">
    <material>Gazebo/CeilingTiled</material>
    <dampingFactor>0.005</dampingFactor>
    <selfCollide>true</selfCollide>
    <turnGravityOff>true</turnGravityOff>
    </gazebo> 
</robot>
