<?xml version="1.0" ?>

<robot name="window_balcony">
  
  <gazebo reference="wbase_bac">
    <material>Gazebo/GrassFloor</material>
  </gazebo>

  <link name="world"/>

  <joint name="wlink_joint_bac1" type="revolute">
    <axis xyz="1 0 0"/>
    <parent link="world"/>
    <origin rpy="0 0 0" xyz="11.6 7.1 1.11"/>
    <limit effort="1000.0" lower="-0" upper="1.97" velocity="0.5"/>
    <child link="wlink_bac1"/>
    <dynamics damping="10" friction="1000"/>
  </joint>
  
  <joint name="wlink_joint_bac2" type="revolute">
    <axis xyz="1 0 0"/>
    <parent link="world"/>
    <origin rpy="0 0 0" xyz="11.6 7.1 1.32"/>
    <limit effort="1000.0" lower="-0" upper="1.97" velocity="0.5"/>
    <child link="wlink_bac2"/>
    <dynamics damping="10" friction="1000"/>
  </joint>
  
  <joint name="wlink_joint_bac3" type="revolute">
    <axis xyz="1 0 0"/>
    <parent link="world"/>
    <origin rpy="0 0 0" xyz="11.6 7.1 1.53"/>
    <limit effort="1000.0" lower="-0" upper="1.97" velocity="0.5"/>
    <child link="wlink_bac3"/>
    <dynamics damping="10" friction="1000"/>
  </joint>
  
  <joint name="wlink_joint_bac4" type="revolute">
    <axis xyz="1 0 0"/>
    <parent link="world"/>
    <origin rpy="0 0 0" xyz="11.6 7.1 1.74"/>
    <limit effort="1000.0" lower="-0" upper="1.97" velocity="0.5"/>
    <child link="wlink_bac4"/>
    <dynamics damping="10" friction="1000"/>
  </joint>
  
  <joint name="wlink_joint_bac5" type="revolute">
    <axis xyz="1 0 0"/>
    <parent link="world"/>
    <origin rpy="0 0 0" xyz="11.6 7.1 1.95"/>
    <limit effort="1000.0" lower="-0" upper="1.97" velocity="0.5"/>
    <child link="wlink_bac5"/>
    <dynamics damping="10" friction="1000"/>
  </joint>
  
  <joint name="wlink_joint_bac6" type="revolute">
    <axis xyz="1 0 0"/>
    <parent link="world"/>
    <origin rpy="0 0 0" xyz="11.6 7.1 2.16"/>
    <limit effort="1000.0" lower="-0" upper="1.97" velocity="0.5"/>
    <child link="wlink_bac6"/>
    <dynamics damping="10" friction="1000"/>
  </joint>
  

  <link name="wlink_bac1">
    <inertial>
      <mass value="10"/>
      <origin xyz="0 0 0"/>
      <inertia ixx="1.0" ixy="0.0" ixz="0.0" iyy="0.1" iyz="0.0" izz="0.1"/>
    </inertial>
    <visual>
      <origin rpy="0 0 0" xyz="0 0 0"/>
      <geometry>
        <box size="1.2 0.02 0.2"/>
      </geometry>
    </visual>
    <collision>
      <origin rpy="0 0 0" xyz="0 0 0"/>
      <geometry>
        <box size="1.2 0.02 0.2"/>
      </geometry>
    </collision>
  </link>
  <gazebo reference="wlink_bac1">
    <material>Gazebo/RustySteel</material>
    <turnGravityOff>true</turnGravityOff>
  </gazebo>

  <link name="wlink_bac2">
    <inertial>
      <mass value="10"/>
      <origin xyz="0 0 0"/>
      <inertia ixx="1.0" ixy="0.0" ixz="0.0" iyy="0.1" iyz="0.0" izz="0.1"/>
    </inertial>
    <visual>
      <origin rpy="0 0 0" xyz="0 0 0"/>
      <geometry>
        <box size="1.2 0.02 0.2"/>
      </geometry>
    </visual>
    <collision>
      <origin rpy="0 0 0" xyz="0 0 0"/>
      <geometry>
        <box size="1.2 0.02 0.2"/>
      </geometry>
    </collision>
  </link>
  <gazebo reference="wlink_bac2">
    <material>Gazebo/RustySteel</material>
    <turnGravityOff>true</turnGravityOff>
  </gazebo>
  
  <link name="wlink_bac3">
    <inertial>
      <mass value="10"/>
      <origin xyz="0 0 0"/>
      <inertia ixx="1.0" ixy="0.0" ixz="0.0" iyy="0.1" iyz="0.0" izz="0.1"/>
    </inertial>
    <visual>
      <origin rpy="0 0 0" xyz="0 0 0"/>
      <geometry>
        <box size="1.2 0.02 0.2"/>
      </geometry>
    </visual>
    <collision>
      <origin rpy="0 0 0" xyz="0 0 0"/>
      <geometry>
        <box size="1.2 0.02 0.2"/>
      </geometry>
    </collision>
  </link>
  <gazebo reference="wlink_bac3">
    <material>Gazebo/RustySteel</material>
    <turnGravityOff>true</turnGravityOff>
  </gazebo>
  
  <link name="wlink_bac4">
    <inertial>
      <mass value="10"/>
      <origin xyz="0 0 0"/>
      <inertia ixx="1.0" ixy="0.0" ixz="0.0" iyy="0.1" iyz="0.0" izz="0.1"/>
    </inertial>
    <visual>
      <origin rpy="0 0 0" xyz="0 0 0"/>
      <geometry>
        <box size="1.2 0.02 0.2"/>
      </geometry>
    </visual>
    <collision>
      <origin rpy="0 0 0" xyz="0 0 0"/>
      <geometry>
        <box size="1.2 0.02 0.2"/>
      </geometry>
    </collision>
  </link>
  <gazebo reference="wlink_bac4">
    <material>Gazebo/RustySteel</material>
    <turnGravityOff>true</turnGravityOff>
  </gazebo>
  
  <link name="wlink_bac5">
    <inertial>
      <mass value="10"/>
      <origin xyz="0 0 0"/>
      <inertia ixx="1.0" ixy="0.0" ixz="0.0" iyy="0.1" iyz="0.0" izz="0.1"/>
    </inertial>
    <visual>
      <origin rpy="0 0 0" xyz="0 0 0"/>
      <geometry>
        <box size="1.2 0.02 0.2"/>
      </geometry>
    </visual>
    <collision>
      <origin rpy="0 0 0" xyz="0 0 0"/>
      <geometry>
        <box size="1.2 0.02 0.2"/>
      </geometry>
    </collision>
  </link>
  <gazebo reference="wlink_bac5">
    <material>Gazebo/RustySteel</material>
    <turnGravityOff>true</turnGravityOff>
  </gazebo>
  
  <link name="wlink_bac6">
    <inertial>
      <mass value="10"/>
      <origin xyz="0 0 0"/>
      <inertia ixx="1.0" ixy="0.0" ixz="0.0" iyy="0.1" iyz="0.0" izz="0.1"/>
    </inertial>
    <visual>
      <origin rpy="0 0 0" xyz="0 0 0"/>
      <geometry>
        <box size="1 0.02 0.2"/>
      </geometry>
    </visual>
    <collision>
      <origin rpy="0 0 0" xyz="0 0 0"/>
      <geometry>
        <box size="1 0.02 0.2"/>
      </geometry>
    </collision>
  </link>
  <gazebo reference="wlink_bac6">
    <material>Gazebo/RustySteel</material>
    <turnGravityOff>true</turnGravityOff>
  </gazebo>-->

</robot>
