<?xml version="1.0" ?>

<robot name="window_kitchenitchen">
  
  <gazebo reference="wbase_kitchen">
    <material>Gazebo/GrassFloor</material>
  </gazebo>

  <link name="world"/>

  <joint name="wlink_joint_kitchen1" type="revolute">
    <axis xyz="0 0 1"/>
    <parent link="world"/>
    <origin rpy="0 0 0" xyz="-0.15 3.385 1.5"/>
    <limit effort="1000.0" lower="-0" upper="1.57" velocity="0.5"/>
    <child link="wlink_kitchen1"/>
    <dynamics damping="10" friction="1000"/>
  </joint>
  
  <joint name="wlink_joint_kitchen2" type="revolute">
    <axis xyz="0 0 1"/>
    <parent link="world"/>
    <origin rpy="0 0 0" xyz="-0.15 3.575 1.5"/>
    <limit effort="1000.0" lower="-0" upper="1.57" velocity="0.5"/>
    <child link="wlink_kitchen2"/>
    <dynamics damping="10" friction="1000"/>
  </joint>
  
  <joint name="wlink_joint_kitchen3" type="revolute">
    <axis xyz="0 0 1"/>
    <parent link="world"/>
    <origin rpy="0 0 0" xyz="-0.15 3.775 1.5"/>
    <limit effort="1000.0" lower="-0" upper="1.57" velocity="0.5"/>
    <child link="wlink_kitchen3"/>
    <dynamics damping="10" friction="1000"/>
  </joint>
  
  <joint name="wlink_joint_kitchen4" type="revolute">
    <axis xyz="0 0 1"/>
    <parent link="world"/>
    <origin rpy="0 0 0" xyz="-0.15 3.975 1.5"/>
    <limit effort="1000.0" lower="-0" upper="1.57" velocity="0.5"/>
    <child link="wlink_kitchen4"/>
    <dynamics damping="10" friction="1000"/>
  </joint>
  
  <joint name="wlink_joint_kitchen5" type="revolute">
    <axis xyz="0 0 1"/>
    <parent link="world"/>
    <origin rpy="0 0 0" xyz="-0.15 4.175 1.5"/>
    <limit effort="1000.0" lower="-0" upper="1.57" velocity="0.5"/>
    <child link="wlink_kitchen5"/>
    <dynamics damping="10" friction="1000"/>
  </joint>
  
  <joint name="wlink_joint_kitchen6" type="revolute">
    <axis xyz="0 0 1"/>
    <parent link="world"/>
    <origin rpy="0 0 0" xyz="-0.15 4.375 1.5"/>
    <limit effort="1000.0" lower="-0" upper="1.57" velocity="0.5"/>
    <child link="wlink_kitchen6"/>
    <dynamics damping="10" friction="1000"/>
  </joint>
  
  <joint name="wlink_joint_kitchen7" type="revolute">
    <axis xyz="0 0 1"/>
    <parent link="world"/>
    <origin rpy="0 0 0" xyz="-0.15 4.575 1.5"/>
    <limit effort="1000.0" lower="-0" upper="1.57" velocity="0.5"/>
    <child link="wlink_kitchen7"/>
    <dynamics damping="10" friction="1000"/>
  </joint>
  
  <joint name="wlink_joint_kitchen8" type="revolute">
    <axis xyz="0 0 1"/>
    <parent link="world"/>
    <origin rpy="0 0 0" xyz="-0.15 4.775 1.5"/>
    <limit effort="1000.0" lower="-0" upper="1.57" velocity="0.5"/>
    <child link="wlink_kitchen8"/>
    <dynamics damping="10" friction="1000"/>
  </joint>
  
  <joint name="wlink_joint_kitchen9" type="revolute">
    <axis xyz="0 0 1"/>
    <parent link="world"/>
    <origin rpy="0 0 0" xyz="-0.15 4.975 1.5"/>
    <limit effort="1000.0" lower="-0" upper="1.57" velocity="0.5"/>
    <child link="wlink_kitchen9"/>
    <dynamics damping="10" friction="1000"/>
  </joint>
  
  <joint name="wlink_joint_kitchen:" type="revolute">
    <axis xyz="0 0 1"/>
    <parent link="world"/>
    <origin rpy="0 0 0" xyz="-0.15 5.175 1.5"/>
    <limit effort="1000.0" lower="-0" upper="1.57" velocity="0.5"/>
    <child link="wlink_kitchen:"/>
    <dynamics damping="10" friction="1000"/>
  </joint>
  

  <link name="wlink_kitchen1">
    <inertial>
      <mass value="1"/>
      <origin xyz="0 0 0"/>
      <inertia ixx="1.0" ixy="0.0" ixz="0.0" iyy="0.1" iyz="0.0" izz="0.1"/>
    </inertial>
    <visual>
      <origin rpy="0 0 1.57" xyz="0 0 0"/>
      <geometry>
        <box size="0.13 0.02 1.5"/>
      </geometry>
    </visual>
    <collision>
      <origin rpy="0 0 1.57" xyz="0 0 0"/>
      <geometry>
        <box size="0.13 0.02 1.5"/>
      </geometry>
    </collision>
  </link>
  <gazebo reference="wlink_kitchen1">
    <material>Gazebo/RustySteel</material>
    <turnGravityOff>true</turnGravityOff>
  </gazebo>

  <link name="wlink_kitchen2">
    <inertial>
      <mass value="10"/>
      <origin xyz="0 0 0"/>
      <inertia ixx="1.0" ixy="0.0" ixz="0.0" iyy="0.1" iyz="0.0" izz="0.1"/>
    </inertial>
    <visual>
      <origin rpy="0 0 1.57" xyz="0 0 0"/>
      <geometry>
        <box size="0.17 0.02 1.5"/>
      </geometry>
    </visual>
    <collision>
      <origin rpy="0 0 1.57" xyz="0 0 0"/>
      <geometry>
        <box size="0.17 0.02 1.5"/>
      </geometry>
    </collision>
  </link>
  <gazebo reference="wlink_kitchen2">
    <material>Gazebo/RustySteel</material>
    <turnGravityOff>true</turnGravityOff>
  </gazebo>
  
  <link name="wlink_kitchen3">
    <inertial>
      <mass value="10"/>
      <origin xyz="0 0 0"/>
      <inertia ixx="1.0" ixy="0.0" ixz="0.0" iyy="0.1" iyz="0.0" izz="0.1"/>
    </inertial>
    <visual>
      <origin rpy="0 0 1.57" xyz="0 0 0"/>
      <geometry>
        <box size="0.17 0.02 1.5"/>
      </geometry>
    </visual>
    <collision>
      <origin rpy="0 0 1.57" xyz="0 0 0"/>
      <geometry>
        <box size="0.17 0.02 1.5"/>
      </geometry>
    </collision>
  </link>
  <gazebo reference="wlink_kitchen3">
    <material>Gazebo/RustySteel</material>
    <turnGravityOff>true</turnGravityOff>
  </gazebo>
  
  <link name="wlink_kitchen4">
    <inertial>
      <mass value="10"/>
      <origin xyz="0 0 0"/>
      <inertia ixx="1.0" ixy="0.0" ixz="0.0" iyy="0.1" iyz="0.0" izz="0.1"/>
    </inertial>
    <visual>
      <origin rpy="0 0 1.57" xyz="0 0 0"/>
      <geometry>
        <box size="0.17 0.02 1.5"/>
      </geometry>
    </visual>
    <collision>
      <origin rpy="0 0 1.57" xyz="0 0 0"/>
      <geometry>
        <box size="0.17 0.02 1.5"/>
      </geometry>
    </collision>
  </link>
  <gazebo reference="wlink_kitchen4">
    <material>Gazebo/RustySteel</material>
    <turnGravityOff>true</turnGravityOff>
  </gazebo>
  
  <link name="wlink_kitchen5">
    <inertial>
      <mass value="10"/>
      <origin xyz="0 0 0"/>
      <inertia ixx="1.0" ixy="0.0" ixz="0.0" iyy="0.1" iyz="0.0" izz="0.1"/>
    </inertial>
    <visual>
      <origin rpy="0 0 1.57" xyz="0 0 0"/>
      <geometry>
        <box size="0.17 0.02 1.5"/>
      </geometry>
    </visual>
    <collision>
      <origin rpy="0 0 1.57" xyz="0 0 0"/>
      <geometry>
        <box size="0.17 0.02 1.5"/>
      </geometry>
    </collision>
  </link>
  <gazebo reference="wlink_kitchen5">
    <material>Gazebo/RustySteel</material>
    <turnGravityOff>true</turnGravityOff>
  </gazebo>

  <link name="wlink_kitchen6">
    <inertial>
      <mass value="10"/>
      <origin xyz="0 0 0"/>
      <inertia ixx="1.0" ixy="0.0" ixz="0.0" iyy="0.1" iyz="0.0" izz="0.1"/>
    </inertial>
    <visual>
      <origin rpy="0 0 1.57" xyz="0 0 0"/>
      <geometry>
        <box size="0.17 0.02 1.5"/>
      </geometry>
    </visual>
    <collision>
      <origin rpy="0 0 1.57" xyz="0 0 0"/>
      <geometry>
        <box size="0.17 0.02 1.5"/>
      </geometry>
    </collision>
  </link>
  <gazebo reference="wlink_kitchen6">
    <material>Gazebo/RustySteel</material>
    <turnGravityOff>true</turnGravityOff>
  </gazebo>
  
  <link name="wlink_kitchen7">
    <inertial>
      <mass value="1"/>
      <origin xyz="0 0 0"/>
      <inertia ixx="1.0" ixy="0.0" ixz="0.0" iyy="0.1" iyz="0.0" izz="0.1"/>
    </inertial>
    <visual>
      <origin rpy="0 0 1.57" xyz="0 0 0"/>
      <geometry>
        <box size="0.17 0.02 1.5"/>
      </geometry>
    </visual>
    <collision>
      <origin rpy="0 0 1.57" xyz="0 0 0"/>
      <geometry>
        <box size="0.17 0.02 1.5"/>
      </geometry>
    </collision>
  </link>
  <gazebo reference="wlink_kitchen7">
    <material>Gazebo/RustySteel</material>
    <turnGravityOff>true</turnGravityOff>
  </gazebo>
  
  <link name="wlink_kitchen8">
    <inertial>
      <mass value="10"/>
      <origin xyz="0 0 0"/>
      <inertia ixx="1.0" ixy="0.0" ixz="0.0" iyy="0.1" iyz="0.0" izz="0.1"/>
    </inertial>
    <visual>
      <origin rpy="0 0 1.57" xyz="0 0 0"/>
      <geometry>
        <box size="0.17 0.02 1.5"/>
      </geometry>
    </visual>
    <collision>
      <origin rpy="0 0 1.57" xyz="0 0 0"/>
      <geometry>
        <box size="0.17 0.02 1.5"/>
      </geometry>
    </collision>
  </link>
  <gazebo reference="wlink_kitchen8">
    <material>Gazebo/RustySteel</material>
    <turnGravityOff>true</turnGravityOff>
  </gazebo>
  
  <link name="wlink_kitchen9">
    <inertial>
      <mass value="10"/>
      <origin xyz="0 0 0"/>
      <inertia ixx="1.0" ixy="0.0" ixz="0.0" iyy="0.1" iyz="0.0" izz="0.1"/>
    </inertial>
    <visual>
      <origin rpy="0 0 1.57" xyz="0 0 0"/>
      <geometry>
        <box size="0.17 0.02 1.5"/>
      </geometry>
    </visual>
    <collision>
      <origin rpy="0 0 1.57" xyz="0 0 0"/>
      <geometry>
        <box size="0.17 0.02 1.5"/>
      </geometry>
    </collision>
  </link>
  <gazebo reference="wlink_kitchen9">
    <material>Gazebo/RustySteel</material>
    <turnGravityOff>true</turnGravityOff>
  </gazebo>
  
  <link name="wlink_kitchen:">
    <inertial>
      <mass value="10"/>
      <origin xyz="0 0 0"/>
      <inertia ixx="1.0" ixy="0.0" ixz="0.0" iyy="0.1" iyz="0.0" izz="0.1"/>
    </inertial>
    <visual>
      <origin rpy="0 0 1.57" xyz="0 0 0"/>
      <geometry>
        <box size="0.17 0.02 1.5"/>
      </geometry>
    </visual>
    <collision>
      <origin rpy="0 0 1.57" xyz="0 0 0"/>
      <geometry>
        <box size="0.17 0.02 1.5"/>
      </geometry>
    </collision>
  </link>
  <gazebo reference="wlink_kitchen:">
    <material>Gazebo/RustySteel</material>
    <turnGravityOff>true</turnGravityOff>
  </gazebo>
</robot>
