<?xml version="1.0" ?>

<robot name="window_bedroom">
  
  <gazebo reference="wbase_bedroom">
    <material>Gazebo/GrassFloor</material>
  </gazebo>

  <link name="world"/>

  <joint name="wlink_joint_bedroom1" type="revolute">
    <axis xyz="0 0 1"/>
    <parent link="world"/>
    <origin rpy="0 0 0" xyz="-0.15 1.575 1.5"/>
    <limit effort="1000.0" lower="-0" upper="1.57" velocity="0.5"/>
    <child link="wlink_bedroom1"/>
    <dynamics damping="10" friction="1000"/>
  </joint>
  
  <joint name="wlink_joint_bedroom2" type="revolute">
    <axis xyz="0 0 1"/>
    <parent link="world"/>
    <origin rpy="0 0 0" xyz="-0.15 1.775 1.5"/>
    <limit effort="1000.0" lower="-0" upper="1.57" velocity="0.5"/>
    <child link="wlink_bedroom2"/>
    <dynamics damping="10" friction="1000"/>
  </joint>
  
  <joint name="wlink_joint_bedroom3" type="revolute">
    <axis xyz="0 0 1"/>
    <parent link="world"/>
    <origin rpy="0 0 0" xyz="-0.15 1.975 1.5"/>
    <limit effort="1000.0" lower="-0" upper="1.57" velocity="0.5"/>
    <child link="wlink_bedroom3"/>
    <dynamics damping="10" friction="1000"/>
  </joint>
  
  <joint name="wlink_joint_bedroom4" type="revolute">
    <axis xyz="0 0 1"/>
    <parent link="world"/>
    <origin rpy="0 0 0" xyz="-0.15 2.175 1.5"/>
    <limit effort="1000.0" lower="-0" upper="1.57" velocity="0.5"/>
    <child link="wlink_bedroom4"/>
    <dynamics damping="10" friction="1000"/>
  </joint>
  
  <joint name="wlink_joint_bedroom5" type="revolute">
    <axis xyz="0 0 1"/>
    <parent link="world"/>
    <origin rpy="0 0 0" xyz="-0.15 2.375 1.5"/>
    <limit effort="1000.0" lower="-0" upper="1.57" velocity="0.5"/>
    <child link="wlink_bedroom5"/>
    <dynamics damping="10" friction="1000"/>
  </joint>
  
  <joint name="wlink_joint_bedroom6" type="revolute">
    <axis xyz="0 0 1"/>
    <parent link="world"/>
    <origin rpy="0 0 0" xyz="-0.15 2.575 1.5"/>
    <limit effort="1000.0" lower="-0" upper="1.57" velocity="0.5"/>
    <child link="wlink_bedroom6"/>
    <dynamics damping="10" friction="1000"/>
  </joint>
  

  <link name="wlink_bedroom1">
    <inertial>
      <mass value="10"/>
      <origin xyz="0 0 0"/>
      <inertia ixx="1.0" ixy="0.0" ixz="0.0" iyy="0.1" iyz="0.0" izz="0.1"/>
    </inertial>
    <visual>
      <origin rpy="0 0 1.57" xyz="0 0 0"/>
      <geometry>
        <box size="0.15 0.02 1.5"/>
      </geometry>
    </visual>
    <collision>
      <origin rpy="0 0 90" xyz="0 0 0"/>
      <geometry>
        <box size="0.15 0.02 1.5"/>
      </geometry>
    </collision>
  </link>
  <gazebo reference="wlink_bedroom1">
    <material>Gazebo/RustySteel</material>
    <turnGravityOff>true</turnGravityOff>
  </gazebo>

  <link name="wlink_bedroom2">
    <inertial>
      <mass value="10"/>
      <origin xyz="0 0 0"/>
      <inertia ixx="1.0" ixy="0.0" ixz="0.0" iyy="0.1" iyz="0.0" izz="0.1"/>
    </inertial>
    <visual>
      <origin rpy="0 0 1.57" xyz="0 0 0"/>
      <geometry>
        <box size="0.17 0.05 1.5"/>
      </geometry>
    </visual>
    <collision>
      <origin rpy="0 0 90" xyz="0 0 0"/>
      <geometry>
        <box size="0.17 0.05 1.5"/>
      </geometry>
    </collision>
  </link>
  <gazebo reference="wlink_bedroom2">
    <material>Gazebo/RustySteel</material>
    <turnGravityOff>true</turnGravityOff>
  </gazebo>
  
  <link name="wlink_bedroom3">
    <inertial>
      <mass value="10"/>
      <origin xyz="0 0 0"/>
      <inertia ixx="1.0" ixy="0.0" ixz="0.0" iyy="0.1" iyz="0.0" izz="0.1"/>
    </inertial>
    <visual>
      <origin rpy="0 0 1.57" xyz="0 0 0"/>
      <geometry>
        <box size="0.17 0.05 1.5"/>
      </geometry>
    </visual>
    <collision>
      <origin rpy="0 0 90" xyz="0 0 0"/>
      <geometry>
        <box size="0.17 0.05 1.5"/>
      </geometry>
    </collision>
  </link>
  <gazebo reference="wlink_bedroom3">
    <material>Gazebo/RustySteel</material>
    <turnGravityOff>true</turnGravityOff>
  </gazebo>
  
  <link name="wlink_bedroom4">
    <inertial>
      <mass value="10"/>
      <origin xyz="0 0 0"/>
      <inertia ixx="1.0" ixy="0.0" ixz="0.0" iyy="0.1" iyz="0.0" izz="0.1"/>
    </inertial>
    <visual>
      <origin rpy="0 0 1.57" xyz="0 0 0"/>
      <geometry>
        <box size="0.17 0.05 1.5"/>
      </geometry>
    </visual>
    <collision>
      <origin rpy="0 0 90" xyz="0 0 0"/>
      <geometry>
        <box size="0.17 0.05 1.5"/>
      </geometry>
    </collision>
  </link>
  <gazebo reference="wlink_bedroom4">
    <material>Gazebo/RustySteel</material>
    <turnGravityOff>true</turnGravityOff>
  </gazebo>
  
  <link name="wlink_bedroom5">
    <inertial>
      <mass value="10"/>
      <origin xyz="0 0 0"/>
      <inertia ixx="1.0" ixy="0.0" ixz="0.0" iyy="0.1" iyz="0.0" izz="0.1"/>
    </inertial>
    <visual>
      <origin rpy="0 0 1.57" xyz="0 0 0"/>
      <geometry>
        <box size="0.18 0.05 1.5"/>
      </geometry>
    </visual>
    <collision>
      <origin rpy="0 0 90" xyz="0 0 0"/>
      <geometry>
        <box size="0.18 0.05 1.5"/>
      </geometry>
    </collision>
  </link>
  <gazebo reference="wlink_bedroom5">
    <material>Gazebo/RustySteel</material>
    <turnGravityOff>true</turnGravityOff>
  </gazebo>
  
  <link name="wlink_bedroom6">
    <inertial>
      <mass value="10"/>
      <origin xyz="0 0 0"/>
      <inertia ixx="1.0" ixy="0.0" ixz="0.0" iyy="0.1" iyz="0.0" izz="0.1"/>
    </inertial>
    <visual>
      <origin rpy="0 0 1.57" xyz="0 0 0"/>
      <geometry>
        <box size="0.18 0.05 1.5"/>
      </geometry>
    </visual>
    <collision>
      <origin rpy="0 0 90" xyz="0 0 0"/>
      <geometry>
        <box size="0.18 0.05 1.5"/>
      </geometry>
    </collision>
  </link>
  <gazebo reference="wlink_bedroom6">
    <material>Gazebo/RustySteel</material>
    <turnGravityOff>true</turnGravityOff>
  </gazebo>

</robot>
