<?xml version="1.0" ?>

<robot name="window_livingroom">
  
  <gazebo reference="wbase_lr">
    <material>Gazebo/GrassFloor</material>
  </gazebo>

  <link name="world"/>

  <joint name="wlink_joint_lr1" type="revolute">
    <axis xyz="0 0 1"/>
    <parent link="world"/>
    <origin rpy="0 0 0" xyz="10.765 5.575 1.5"/>
    <limit effort="1000.0" lower="-0" upper="1.57" velocity="0.5"/>
    <child link="wlink_lr1"/>
    <dynamics damping="10" friction="1000"/>
  </joint>
  
  <joint name="wlink_joint_lr2" type="revolute">
    <axis xyz="0 0 1"/>
    <parent link="world"/>
    <origin rpy="0 0 0" xyz="10.765 5.375 1.5"/>
    <limit effort="1000.0" lower="-0" upper="1.57" velocity="0.5"/>
    <child link="wlink_lr2"/>
    <dynamics damping="10" friction="1000"/>
  </joint>
  
  <joint name="wlink_joint_lr3" type="revolute">
    <axis xyz="0 0 1"/>
    <parent link="world"/>
    <origin rpy="0 0 0" xyz="10.765 5.175 1.5"/>
    <limit effort="1000.0" lower="-0" upper="1.57" velocity="0.5"/>
    <child link="wlink_lr3"/>
    <dynamics damping="10" friction="1000"/>
  </joint>
  
  <joint name="wlink_joint_lr4" type="revolute">
    <axis xyz="0 0 1"/>
    <parent link="world"/>
    <origin rpy="0 0 0" xyz="10.765 4.975 1.5"/>
    <limit effort="1000.0" lower="-0" upper="1.57" velocity="0.5"/>
    <child link="wlink_lr4"/>
    <dynamics damping="10" friction="1000"/>
  </joint>
  
  <joint name="wlink_joint_lr5" type="revolute">
    <axis xyz="0 0 1"/>
    <parent link="world"/>
    <origin rpy="0 0 0" xyz="10.765 4.775 1.5"/>
    <limit effort="1000.0" lower="-0" upper="1.57" velocity="0.5"/>
    <child link="wlink_lr5"/>
    <dynamics damping="10" friction="1000"/>
  </joint>
  
  <joint name="wlink_joint_lr6" type="revolute">
    <axis xyz="0 0 1"/>
    <parent link="world"/>
    <origin rpy="0 0 0" xyz="10.765 4.575 1.5"/>
    <limit effort="1000.0" lower="-0" upper="1.57" velocity="0.5"/>
    <child link="wlink_lr6"/>
    <dynamics damping="10" friction="1000"/>
  </joint>
  
  <joint name="wlink_joint_lr7" type="revolute">
    <axis xyz="0 0 1"/>
    <parent link="world"/>
    <origin rpy="0 0 0" xyz="10.765 4.375 1.5"/>
    <limit effort="1000.0" lower="-0" upper="1.57" velocity="0.5"/>
    <child link="wlink_lr7"/>
    <dynamics damping="10" friction="1000"/>
  </joint>
  
  <joint name="wlink_joint_lr8" type="revolute">
    <axis xyz="0 0 1"/>
    <parent link="world"/>
    <origin rpy="0 0 0" xyz="10.765 4.175 1.5"/>
    <limit effort="1000.0" lower="-0" upper="1.57" velocity="0.5"/>
    <child link="wlink_lr8"/>
    <dynamics damping="10" friction="1000"/>
  </joint>
  
  <joint name="wlink_joint_lr9" type="revolute">
    <axis xyz="0 0 1"/>
    <parent link="world"/>
    <origin rpy="0 0 0" xyz="10.765 3.975 1.5"/>
    <limit effort="1000.0" lower="-0" upper="1.57" velocity="0.5"/>
    <child link="wlink_lr9"/>
    <dynamics damping="10" friction="1000"/>
  </joint>
  
  <joint name="wlink_joint_lr:" type="revolute">
    <axis xyz="0 0 1"/>
    <parent link="world"/>
    <origin rpy="0 0 0" xyz="10.765 3.775 1.5"/>
    <limit effort="1000.0" lower="-0" upper="1.57" velocity="0.5"/>
    <child link="wlink_lr:"/>
    <dynamics damping="10" friction="1000"/>
  </joint>
  
  <joint name="wlink_joint_lr;" type="revolute">
    <axis xyz="0 0 1"/>
    <parent link="world"/>
    <origin rpy="0 0 0" xyz="10.765 3.575 1.5"/>
    <limit effort="1000.0" lower="-0" upper="1.57" velocity="0.5"/>
    <child link="wlink_lr;"/>
    <dynamics damping="10" friction="1000"/>
  </joint>
  

  <link name="wlink_lr1">
    <inertial>
      <mass value="10"/>
      <origin xyz="0 0 0"/>
      <inertia ixx="1.0" ixy="0.0" ixz="0.0" iyy="0.1" iyz="0.0" izz="0.1"/>
    </inertial>
    <visual>
      <origin rpy="0 0 1.57" xyz="0 0 0"/>
      <geometry>
        <box size="0.15 0.02 1.5"/>
      </geometry>
    </visual>
    <collision>
      <origin rpy="0 0 90" xyz="0 0 0"/>
      <geometry>
        <box size="0.15 0.02 1.5"/>
      </geometry>
    </collision>
  </link>
  <gazebo reference="wlink_lr1">
    <material>Gazebo/RustySteel</material>
    <turnGravityOff>true</turnGravityOff>
  </gazebo>

  <link name="wlink_lr2">
    <inertial>
      <mass value="10"/>
      <origin xyz="0 0 0"/>
      <inertia ixx="1.0" ixy="0.0" ixz="0.0" iyy="0.1" iyz="0.0" izz="0.1"/>
    </inertial>
    <visual>
      <origin rpy="0 0 1.57" xyz="0 0 0"/>
      <geometry>
        <box size="0.17 0.05 1.5"/>
      </geometry>
    </visual>
    <collision>
      <origin rpy="0 0 90" xyz="0 0 0"/>
      <geometry>
        <box size="0.17 0.05 1.5"/>
      </geometry>
    </collision>
  </link>
  <gazebo reference="wlink_lr2">
    <material>Gazebo/RustySteel</material>
    <turnGravityOff>true</turnGravityOff>
  </gazebo>
  
  <link name="wlink_lr3">
    <inertial>
      <mass value="10"/>
      <origin xyz="0 0 0"/>
      <inertia ixx="1.0" ixy="0.0" ixz="0.0" iyy="0.1" iyz="0.0" izz="0.1"/>
    </inertial>
    <visual>
      <origin rpy="0 0 1.57" xyz="0 0 0"/>
      <geometry>
        <box size="0.17 0.05 1.5"/>
      </geometry>
    </visual>
    <collision>
      <origin rpy="0 0 90" xyz="0 0 0"/>
      <geometry>
        <box size="0.17 0.05 1.5"/>
      </geometry>
    </collision>
  </link>
  <gazebo reference="wlink_lr3">
    <material>Gazebo/RustySteel</material>
    <turnGravityOff>true</turnGravityOff>
  </gazebo>
  
  <link name="wlink_lr4">
    <inertial>
      <mass value="10"/>
      <origin xyz="0 0 0"/>
      <inertia ixx="1.0" ixy="0.0" ixz="0.0" iyy="0.1" iyz="0.0" izz="0.1"/>
    </inertial>
    <visual>
      <origin rpy="0 0 1.57" xyz="0 0 0"/>
      <geometry>
        <box size="0.17 0.05 1.5"/>
      </geometry>
    </visual>
    <collision>
      <origin rpy="0 0 90" xyz="0 0 0"/>
      <geometry>
        <box size="0.17 0.05 1.5"/>
      </geometry>
    </collision>
  </link>
  <gazebo reference="wlink_lr4">
    <material>Gazebo/RustySteel</material>
    <turnGravityOff>true</turnGravityOff>
  </gazebo>
  
  <link name="wlink_lr5">
    <inertial>
      <mass value="10"/>
      <origin xyz="0 0 0"/>
      <inertia ixx="1.0" ixy="0.0" ixz="0.0" iyy="0.1" iyz="0.0" izz="0.1"/>
    </inertial>
    <visual>
      <origin rpy="0 0 1.57" xyz="0 0 0"/>
      <geometry>
        <box size="0.17 0.05 1.5"/>
      </geometry>
    </visual>
    <collision>
      <origin rpy="0 0 90" xyz="0 0 0"/>
      <geometry>
        <box size="0.17 0.05 1.5"/>
      </geometry>
    </collision>
  </link>
  <gazebo reference="wlink_lr5">
    <material>Gazebo/RustySteel</material>
    <turnGravityOff>true</turnGravityOff>
  </gazebo>

  <link name="wlink_lr6">
    <inertial>
      <mass value="10"/>
      <origin xyz="0 0 0"/>
      <inertia ixx="1.0" ixy="0.0" ixz="0.0" iyy="0.1" iyz="0.0" izz="0.1"/>
    </inertial>
    <visual>
      <origin rpy="0 0 1.57" xyz="0 0 0"/>
      <geometry>
        <box size="0.17 0.05 1.5"/>
      </geometry>
    </visual>
    <collision>
      <origin rpy="0 0 90" xyz="0 0 0"/>
      <geometry>
        <box size="0.17 0.05 1.5"/>
      </geometry>
    </collision>
  </link>
  <gazebo reference="wlink_lr6">
    <material>Gazebo/RustySteel</material>
    <turnGravityOff>true</turnGravityOff>
  </gazebo>
  
  <link name="wlink_lr7">
    <inertial>
      <mass value="10"/>
      <origin xyz="0 0 0"/>
      <inertia ixx="1.0" ixy="0.0" ixz="0.0" iyy="0.1" iyz="0.0" izz="0.1"/>
    </inertial>
    <visual>
      <origin rpy="0 0 1.57" xyz="0 0 0"/>
      <geometry>
        <box size="0.17 0.05 1.5"/>
      </geometry>
    </visual>
    <collision>
      <origin rpy="0 0 90" xyz="0 0 0"/>
      <geometry>
        <box size="0.17 0.05 1.5"/>
      </geometry>
    </collision>
  </link>
  <gazebo reference="wlink_lr7">
    <material>Gazebo/RustySteel</material>
    <turnGravityOff>true</turnGravityOff>
  </gazebo>
  
  <link name="wlink_lr8">
    <inertial>
      <mass value="10"/>
      <origin xyz="0 0 0"/>
      <inertia ixx="1.0" ixy="0.0" ixz="0.0" iyy="0.1" iyz="0.0" izz="0.1"/>
    </inertial>
    <visual>
      <origin rpy="0 0 1.57" xyz="0 0 0"/>
      <geometry>
        <box size="0.17 0.05 1.5"/>
      </geometry>
    </visual>
    <collision>
      <origin rpy="0 0 90" xyz="0 0 0"/>
      <geometry>
        <box size="0.17 0.05 1.5"/>
      </geometry>
    </collision>
  </link>
  <gazebo reference="wlink_lr8">
    <material>Gazebo/RustySteel</material>
    <turnGravityOff>true</turnGravityOff>
  </gazebo>
  
  <link name="wlink_lr9">
    <inertial>
      <mass value="10"/>
      <origin xyz="0 0 0"/>
      <inertia ixx="1.0" ixy="0.0" ixz="0.0" iyy="0.1" iyz="0.0" izz="0.1"/>
    </inertial>
    <visual>
      <origin rpy="0 0 1.57" xyz="0 0 0"/>
      <geometry>
        <box size="0.17 0.05 1.5"/>
      </geometry>
    </visual>
    <collision>
      <origin rpy="0 0 90" xyz="0 0 0"/>
      <geometry>
        <box size="0.17 0.05 1.5"/>
      </geometry>
    </collision>
  </link>
  <gazebo reference="wlink_lr9">
    <material>Gazebo/RustySteel</material>
    <turnGravityOff>true</turnGravityOff>
  </gazebo>
  
  <link name="wlink_lr:">
    <inertial>
      <mass value="10"/>
      <origin xyz="0 0 0"/>
      <inertia ixx="1.0" ixy="0.0" ixz="0.0" iyy="0.1" iyz="0.0" izz="0.1"/>
    </inertial>
    <visual>
      <origin rpy="0 0 1.57" xyz="0 0 0"/>
      <geometry>
        <box size="0.17 0.05 1.5"/>
      </geometry>
    </visual>
    <collision>
      <origin rpy="0 0 90" xyz="0 0 0"/>
      <geometry>
        <box size="0.17 0.05 1.5"/>
      </geometry>
    </collision>
  </link>
  <gazebo reference="wlink_lr:">
    <material>Gazebo/RustySteel</material>
    <turnGravityOff>true</turnGravityOff>
  </gazebo>
  
  <link name="wlink_lr;">
    <inertial>
      <mass value="10"/>
      <origin xyz="0 0 0"/>
      <inertia ixx="1.0" ixy="0.0" ixz="0.0" iyy="0.1" iyz="0.0" izz="0.1"/>
    </inertial>
    <visual>
      <origin rpy="0 0 1.57" xyz="0 0 0"/>
      <geometry>
        <box size="0.17 0.05 1.5"/>
      </geometry>
    </visual>
    <collision>
      <origin rpy="0 0 90" xyz="0 0 0"/>
      <geometry>
        <box size="0.17 0.05 1.5"/>
      </geometry>
    </collision>
  </link>
  <gazebo reference="wlink_lr;">
    <material>Gazebo/RustySteel</material>
    <turnGravityOff>true</turnGravityOff>
  </gazebo>
  
  
</robot>
